Workbook

Sheet 📱 各班抽查登記表
A1: 26-27 學年 學生書包秤重抽查登記表 | J1: 超重原因代號及說明 | K1: 1) 書包材質偏重
K2: 2) 水樽材質或盛水很重
K3: 3) 書本數量多
A4: 抽查總目標 | C4: 已輸入測量人數 | E4: 達標人數 (<=15%) | G4: 超重人數 (>15%) | K4: 4) 作業本數量多
A5: ="220 人" -> 220 人 | C5: =COUNTIF(F8:F227, ">0") & " 人" -> 0 人 | E5: =COUNTIF(H8:H227, "達標") & " 人" -> 0 人 | G5: =COUNTIF(H8:H227, "超重") & " 人" -> 0 人 | K5: 5) 文具及其他物品的數量多
K6: 6) 其他(須註明)
A7: 抽查 序號 | B7: 班別 | C7: 座號 / 學號 (請輸入) | D7: 學生姓名 | E7: 學生體重 (kg) | F7: 書包重量 (kg) (請輸入) | G7: 書包佔體重% (自動計算) | H7: 評定結果 (<=15%達標) | I7: 超重原因代號 (超重者請點選) | J7: 備註 / 其他原因說明
A8: 1 | B8: P1A | D8: =IFERROR(VLOOKUP(B8&"-"&C8, '💾 學生體重資料庫'!$A:$I, 4, FALSE), "") | E8: =IFERROR(VLOOKUP(B8&"-"&C8, '💾 學生體重資料庫'!$A:$I, 8, FALSE), "") | G8: =IF(OR(NOT(ISNUMBER(E8)), NOT(ISNUMBER(F8)), E8=0), "", F8/E8) | H8: =IF(G8="", "", IF(G8<=0.15, "達標", "超重"))
A9: 2 | B9: P1A | D9: =IFERROR(VLOOKUP(B9&"-"&C9, '💾 學生體重資料庫'!$A:$I, 4, FALSE), "") | E9: =IFERROR(VLOOKUP(B9&"-"&C9, '💾 學生體重資料庫'!$A:$I, 8, FALSE), "") | G9: =IF(OR(NOT(ISNUMBER(E9)), NOT(ISNUMBER(F9)), E9=0), "", F9/E9) | H9: =IF(G9="", "", IF(G9<=0.15, "達標", "超重"))
A10: 3 | B10: P1A | D10: =IFERROR(VLOOKUP(B10&"-"&C10, '💾 學生體重資料庫'!$A:$I, 4, FALSE), "") | E10: =IFERROR(VLOOKUP(B10&"-"&C10, '💾 學生體重資料庫'!$A:$I, 8, FALSE), "") | G10: =IF(OR(NOT(ISNUMBER(E10)), NOT(ISNUMBER(F10)), E10=0), "", F10/E10) | H10: =IF(G10="", "", IF(G10<=0.15, "達標", "超重"))
A11: 4 | B11: P1A | D11: =IFERROR(VLOOKUP(B11&"-"&C11, '💾 學生體重資料庫'!$A:$I, 4, FALSE), "") | E11: =IFERROR(VLOOKUP(B11&"-"&C11, '💾 學生體重資料庫'!$A:$I, 8, FALSE), "") | G11: =IF(OR(NOT(ISNUMBER(E11)), NOT(ISNUMBER(F11)), E11=0), "", F11/E11) | H11: =IF(G11="", "", IF(G11<=0.15, "達標", "超重"))
A12: 5 | B12: P1A | D12: =IFERROR(VLOOKUP(B12&"-"&C12, '💾 學生體重資料庫'!$A:$I, 4, FALSE), "") | E12: =IFERROR(VLOOKUP(B12&"-"&C12, '💾 學生體重資料庫'!$A:$I, 8, FALSE), "") | G12: =IF(OR(NOT(ISNUMBER(E12)), NOT(ISNUMBER(F12)), E12=0), "", F12/E12) | H12: =IF(G12="", "", IF(G12<=0.15, "達標", "超重"))
A13: 6 | B13: P1A | D13: =IFERROR(VLOOKUP(B13&"-"&C13, '💾 學生體重資料庫'!$A:$I, 4, FALSE), "") | E13: =IFERROR(VLOOKUP(B13&"-"&C13, '💾 學生體重資料庫'!$A:$I, 8, FALSE), "") | G13: =IF(OR(NOT(ISNUMBER(E13)), NOT(ISNUMBER(F13)), E13=0), "", F13/E13) | H13: =IF(G13="", "", IF(G13<=0.15, "達標", "超重"))
A14: 7 | B14: P1A | D14: =IFERROR(VLOOKUP(B14&"-"&C14, '💾 學生體重資料庫'!$A:$I, 4, FALSE), "") | E14: =IFERROR(VLOOKUP(B14&"-"&C14, '💾 學生體重資料庫'!$A:$I, 8, FALSE), "") | G14: =IF(OR(NOT(ISNUMBER(E14)), NOT(ISNUMBER(F14)), E14=0), "", F14/E14) | H14: =IF(G14="", "", IF(G14<=0.15, "達標", "超重"))
A15: 8 | B15: P1A | D15: =IFERROR(VLOOKUP(B15&"-"&C15, '💾 學生體重資料庫'!$A:$I, 4, FALSE), "") | E15: =IFERROR(VLOOKUP(B15&"-"&C15, '💾 學生體重資料庫'!$A:$I, 8, FALSE), "") | G15: =IF(OR(NOT(ISNUMBER(E15)), NOT(ISNUMBER(F15)), E15=0), "", F15/E15) | H15: =IF(G15="", "", IF(G15<=0.15, "達標", "超重"))
A16: 9 | B16: P1A | D16: =IFERROR(VLOOKUP(B16&"-"&C16, '💾 學生體重資料庫'!$A:$I, 4, FALSE), "") | E16: =IFERROR(VLOOKUP(B16&"-"&C16, '💾 學生體重資料庫'!$A:$I, 8, FALSE), "") | G16: =IF(OR(NOT(ISNUMBER(E16)), NOT(ISNUMBER(F16)), E16=0), "", F16/E16) | H16: =IF(G16="", "", IF(G16<=0.15, "達標", "超重"))
A17: 10 | B17: P1A | D17: =IFERROR(VLOOKUP(B17&"-"&C17, '💾 學生體重資料庫'!$A:$I, 4, FALSE), "") | E17: =IFERROR(VLOOKUP(B17&"-"&C17, '💾 學生體重資料庫'!$A:$I, 8, FALSE), "") | G17: =IF(OR(NOT(ISNUMBER(E17)), NOT(ISNUMBER(F17)), E17=0), "", F17/E17) | H17: =IF(G17="", "", IF(G17<=0.15, "達標", "超重"))
A18: 11 | B18: P1A | D18: =IFERROR(VLOOKUP(B18&"-"&C18, '💾 學生體重資料庫'!$A:$I, 4, FALSE), "") | E18: =IFERROR(VLOOKUP(B18&"-"&C18, '💾 學生體重資料庫'!$A:$I, 8, FALSE), "") | G18: =IF(OR(NOT(ISNUMBER(E18)), NOT(ISNUMBER(F18)), E18=0), "", F18/E18) | H18: =IF(G18="", "", IF(G18<=0.15, "達標", "超重"))
A19: 12 | B19: P1B | D19: =IFERROR(VLOOKUP(B19&"-"&C19, '💾 學生體重資料庫'!$A:$I, 4, FALSE), "") | E19: =IFERROR(VLOOKUP(B19&"-"&C19, '💾 學生體重資料庫'!$A:$I, 8, FALSE), "") | G19: =IF(OR(NOT(ISNUMBER(E19)), NOT(ISNUMBER(F19)), E19=0), "", F19/E19) | H19: =IF(G19="", "", IF(G19<=0.15, "達標", "超重"))
... A227: 220 | B227: P6D | D227: =IFERROR(VLOOKUP(B227&"-"&C227, '💾 學生體重資料庫'!$A:$I, 4, FALSE), "") | E227: =IFERROR(VLOOKUP(B227&"-"&C227, '💾 學生體重資料庫'!$A:$I, 8, FALSE), "") | G227: =IF(OR(NOT(ISNUMBER(E227)), NOT(ISNUMBER(F227)), E227=0), "", F227/E227) | H227: =IF(G227="", "", IF(G227<=0.15, "達標", "超重"))

Sheet 📊 全校各班抽查總表
A1: 🏫 26-27 學年 學生書包秤重全校抽查即時彙整總表
A2: 特點：本總表與『📱 各班抽查登記表』100% 即時同步。各班修改數據時，全校統計、原因占比及各班進度即時自動重算。
A4: 一、 全校抽查即時整體指標 (100% 動態連動)
A6: 全校抽查目標人數 | C6: 全校已測量人數 | E6: 全校達標人數 (<=15%) | G6: 全校超重人數 (>15%)
A7: ="220 人" -> 220 人 | C7: =COUNTIF('📱 各班抽查登記表'!F8:F227, ">0") & " 人" -> 0 人 | E7: =COUNTIF('📱 各班抽查登記表'!H8:H227, "達標") & " 人" -> 0 人 | G7: =COUNTIF('📱 各班抽查登記表'!H8:H227, "超重") & " 人" -> 0 人
A9: 二、 全校超重原因即時統計與分布 (含『體重過輕』項)
A11: 超重原因代號 | B11: 人數 (人) | C11: 佔超重總人數比例 (%) | D11: 超重原因說明
A12: 1) | B12: =COUNTIF('📱 各班抽查登記表'!$I$8:$I$227, "*1)*") -> 0 | C12: =IF(COUNTIF('📱 各班抽查登記表'!$H$8:$H$227, "超重")=0, 0, B12/COUNTIF('📱 各班抽查登記表'!$H$8:$H$227, "超重")) -> 0 | D12: 1) 書包材質偏重
A13: 2) | B13: =COUNTIF('📱 各班抽查登記表'!$I$8:$I$227, "*2)*") -> 0 | C13: =IF(COUNTIF('📱 各班抽查登記表'!$H$8:$H$227, "超重")=0, 0, B13/COUNTIF('📱 各班抽查登記表'!$H$8:$H$227, "超重")) -> 0 | D13: 2) 水樽材質或盛水很重
A14: 3) | B14: =COUNTIF('📱 各班抽查登記表'!$I$8:$I$227, "*3)*") -> 0 | C14: =IF(COUNTIF('📱 各班抽查登記表'!$H$8:$H$227, "超重")=0, 0, B14/COUNTIF('📱 各班抽查登記表'!$H$8:$H$227, "超重")) -> 0 | D14: 3) 書本數量多
A15: 4) | B15: =COUNTIF('📱 各班抽查登記表'!$I$8:$I$227, "*4)*") -> 0 | C15: =IF(COUNTIF('📱 各班抽查登記表'!$H$8:$H$227, "超重")=0, 0, B15/COUNTIF('📱 各班抽查登記表'!$H$8:$H$227, "超重")) -> 0 | D15: 4) 作業本數量多
A16: 5) | B16: =COUNTIF('📱 各班抽查登記表'!$I$8:$I$227, "*5)*") -> 0 | C16: =IF(COUNTIF('📱 各班抽查登記表'!$H$8:$H$227, "超重")=0, 0, B16/COUNTIF('📱 各班抽查登記表'!$H$8:$H$227, "超重")) -> 0 | D16: 5) 文具及其他物品的數量多
A17: 6) | B17: =COUNTIF('📱 各班抽查登記表'!$I$8:$I$227, "*6)*") -> 0 | C17: =IF(COUNTIF('📱 各班抽查登記表'!$H$8:$H$227, "超重")=0, 0, B17/COUNTIF('📱 各班抽查登記表'!$H$8:$H$227, "超重")) -> 0 | D17: 6) 其他(須註明)
A19: 三、 全校各班抽查即時統計一覽表 (20 班對比)
A21: 班別 | B21: 抽查目標 | C21: 已測量人數 | D21: 達標人數 | E21: 超重人數 | F21: 班級達標率 (%) | G21: 班級超重率 (%) | H21: 即時狀態
A22: P1A | B22: 11 | C22: =COUNTIFS('📱 各班抽查登記表'!$B$8:$B$227, "P1A", '📱 各班抽查登記表'!$F$8:$F$227, ">0") -> 0 | D22: =COUNTIFS('📱 各班抽查登記表'!$B$8:$B$227, "P1A", '📱 各班抽查登記表'!$H$8:$H$227, "達標") -> 0 | E22: =COUNTIFS('📱 各班抽查登記表'!$B$8:$B$227, "P1A", '📱 各班抽查登記表'!$H$8:$H$227, "超重") -> 0 | F22: =IF(C22=0, "", D22/C22) | G22: =IF(C22=0, "", E22/C22) | H22: =IF(C22=0, "未開始", IF(C22<11, "登記中", "已完成")) -> 未開始
A23: P1B | B23: 11 | C23: =COUNTIFS('📱 各班抽查登記表'!$B$8:$B$227, "P1B", '📱 各班抽查登記表'!$F$8:$F$227, ">0") -> 0 | D23: =COUNTIFS('📱 各班抽查登記表'!$B$8:$B$227, "P1B", '📱 各班抽查登記表'!$H$8:$H$227, "達標") -> 0 | E23: =COUNTIFS('📱 各班抽查登記表'!$B$8:$B$227, "P1B", '📱 各班抽查登記表'!$H$8:$H$227, "超重") -> 0 | F23: =IF(C23=0, "", D23/C23) | G23: =IF(C23=0, "", E23/C23) | H23: =IF(C23=0, "未開始", IF(C23<11, "登記中", "已完成")) -> 未開始
A24: P1C | B24: 11 | C24: =COUNTIFS('📱 各班抽查登記表'!$B$8:$B$227, "P1C", '📱 各班抽查登記表'!$F$8:$F$227, ">0") -> 0 | D24: =COUNTIFS('📱 各班抽查登記表'!$B$8:$B$227, "P1C", '📱 各班抽查登記表'!$H$8:$H$227, "達標") -> 0 | E24: =COUNTIFS('📱 各班抽查登記表'!$B$8:$B$227, "P1C", '📱 各班抽查登記表'!$H$8:$H$227, "超重") -> 0 | F24: =IF(C24=0, "", D24/C24) | G24: =IF(C24=0, "", E24/C24) | H24: =IF(C24=0, "未開始", IF(C24<11, "登記中", "已完成")) -> 未開始
A25: P2A | B25: 11 | C25: =COUNTIFS('📱 各班抽查登記表'!$B$8:$B$227, "P2A", '📱 各班抽查登記表'!$F$8:$F$227, ">0") -> 0 | D25: =COUNTIFS('📱 各班抽查登記表'!$B$8:$B$227, "P2A", '📱 各班抽查登記表'!$H$8:$H$227, "達標") -> 0 | E25: =COUNTIFS('📱 各班抽查登記表'!$B$8:$B$227, "P2A", '📱 各班抽查登記表'!$H$8:$H$227, "超重") -> 0 | F25: =IF(C25=0, "", D25/C25) | G25: =IF(C25=0, "", E25/C25) | H25: =IF(C25=0, "未開始", IF(C25<11, "登記中", "已完成")) -> 未開始
A26: P2B | B26: 11 | C26: =COUNTIFS('📱 各班抽查登記表'!$B$8:$B$227, "P2B", '📱 各班抽查登記表'!$F$8:$F$227, ">0") -> 0 | D26: =COUNTIFS('📱 各班抽查登記表'!$B$8:$B$227, "P2B", '📱 各班抽查登記表'!$H$8:$H$227, "達標") -> 0 | E26: =COUNTIFS('📱 各班抽查登記表'!$B$8:$B$227, "P2B", '📱 各班抽查登記表'!$H$8:$H$227, "超重") -> 0 | F26: =IF(C26=0, "", D26/C26) | G26: =IF(C26=0, "", E26/C26) | H26: =IF(C26=0, "未開始", IF(C26<11, "登記中", "已完成")) -> 未開始
A27: P2C | B27: 11 | C27: =COUNTIFS('📱 各班抽查登記表'!$B$8:$B$227, "P2C", '📱 各班抽查登記表'!$F$8:$F$227, ">0") -> 0 | D27: =COUNTIFS('📱 各班抽查登記表'!$B$8:$B$227, "P2C", '📱 各班抽查登記表'!$H$8:$H$227, "達標") -> 0 | E27: =COUNTIFS('📱 各班抽查登記表'!$B$8:$B$227, "P2C", '📱 各班抽查登記表'!$H$8:$H$227, "超重") -> 0 | F27: =IF(C27=0, "", D27/C27) | G27: =IF(C27=0, "", E27/C27) | H27: =IF(C27=0, "未開始", IF(C27<11, "登記中", "已完成")) -> 未開始
A28: P3A | B28: 11 | C28: =COUNTIFS('📱 各班抽查登記表'!$B$8:$B$227, "P3A", '📱 各班抽查登記表'!$F$8:$F$227, ">0") -> 0 | D28: =COUNTIFS('📱 各班抽查登記表'!$B$8:$B$227, "P3A", '📱 各班抽查登記表'!$H$8:$H$227, "達標") -> 0 | E28: =COUNTIFS('📱 各班抽查登記表'!$B$8:$B$227, "P3A", '📱 各班抽查登記表'!$H$8:$H$227, "超重") -> 0 | F28: =IF(C28=0, "", D28/C28) | G28: =IF(C28=0, "", E28/C28) | H28: =IF(C28=0, "未開始", IF(C28<11, "登記中", "已完成")) -> 未開始
A29: P3B | B29: 11 | C29: =COUNTIFS('📱 各班抽查登記表'!$B$8:$B$227, "P3B", '📱 各班抽查登記表'!$F$8:$F$227, ">0") -> 0 | D29: =COUNTIFS('📱 各班抽查登記表'!$B$8:$B$227, "P3B", '📱 各班抽查登記表'!$H$8:$H$227, "達標") -> 0 | E29: =COUNTIFS('📱 各班抽查登記表'!$B$8:$B$227, "P3B", '📱 各班抽查登記表'!$H$8:$H$227, "超重") -> 0 | F29: =IF(C29=0, "", D29/C29) | G29: =IF(C29=0, "", E29/C29) | H29: =IF(C29=0, "未開始", IF(C29<11, "登記中", "已完成")) -> 未開始
A30: P3C | B30: 11 | C30: =COUNTIFS('📱 各班抽查登記表'!$B$8:$B$227, "P3C", '📱 各班抽查登記表'!$F$8:$F$227, ">0") -> 0 | D30: =COUNTIFS('📱 各班抽查登記表'!$B$8:$B$227, "P3C", '📱 各班抽查登記表'!$H$8:$H$227, "達標") -> 0 | E30: =COUNTIFS('📱 各班抽查登記表'!$B$8:$B$227, "P3C", '📱 各班抽查登記表'!$H$8:$H$227, "超重") -> 0 | F30: =IF(C30=0, "", D30/C30) | G30: =IF(C30=0, "", E30/C30) | H30: =IF(C30=0, "未開始", IF(C30<11, "登記中", "已完成")) -> 未開始
A31: P3D | B31: 11 | C31: =COUNTIFS('📱 各班抽查登記表'!$B$8:$B$227, "P3D", '📱 各班抽查登記表'!$F$8:$F$227, ">0") -> 0 | D31: =COUNTIFS('📱 各班抽查登記表'!$B$8:$B$227, "P3D", '📱 各班抽查登記表'!$H$8:$H$227, "達標") -> 0 | E31: =COUNTIFS('📱 各班抽查登記表'!$B$8:$B$227, "P3D", '📱 各班抽查登記表'!$H$8:$H$227, "超重") -> 0 | F31: =IF(C31=0, "", D31/C31) | G31: =IF(C31=0, "", E31/C31) | H31: =IF(C31=0, "未開始", IF(C31<11, "登記中", "已完成")) -> 未開始
A32: P4A | B32: 11 | C32: =COUNTIFS('📱 各班抽查登記表'!$B$8:$B$227, "P4A", '📱 各班抽查登記表'!$F$8:$F$227, ">0") -> 0 | D32: =COUNTIFS('📱 各班抽查登記表'!$B$8:$B$227, "P4A", '📱 各班抽查登記表'!$H$8:$H$227, "達標") -> 0 | E32: =COUNTIFS('📱 各班抽查登記表'!$B$8:$B$227, "P4A", '📱 各班抽查登記表'!$H$8:$H$227, "超重") -> 0 | F32: =IF(C32=0, "", D32/C32) | G32: =IF(C32=0, "", E32/C32) | H32: =IF(C32=0, "未開始", IF(C32<11, "登記中", "已完成")) -> 未開始
A33: P4B | B33: 11 | C33: =COUNTIFS('📱 各班抽查登記表'!$B$8:$B$227, "P4B", '📱 各班抽查登記表'!$F$8:$F$227, ">0") -> 0 | D33: =COUNTIFS('📱 各班抽查登記表'!$B$8:$B$227, "P4B", '📱 各班抽查登記表'!$H$8:$H$227, "達標") -> 0 | E33: =COUNTIFS('📱 各班抽查登記表'!$B$8:$B$227, "P4B", '📱 各班抽查登記表'!$H$8:$H$227, "超重") -> 0 | F33: =IF(C33=0, "", D33/C33) | G33: =IF(C33=0, "", E33/C33) | H33: =IF(C33=0, "未開始", IF(C33<11, "登記中", "已完成")) -> 未開始
A34: P4C | B34: 11 | C34: =COUNTIFS('📱 各班抽查登記表'!$B$8:$B$227, "P4C", '📱 各班抽查登記表'!$F$8:$F$227, ">0") -> 0 | D34: =COUNTIFS('📱 各班抽查登記表'!$B$8:$B$227, "P4C", '📱 各班抽查登記表'!$H$8:$H$227, "達標") -> 0 | E34: =COUNTIFS('📱 各班抽查登記表'!$B$8:$B$227, "P4C", '📱 各班抽查登記表'!$H$8:$H$227, "超重") -> 0 | F34: =IF(C34=0, "", D34/C34) | G34: =IF(C34=0, "", E34/C34) | H34: =IF(C34=0, "未開始", IF(C34<11, "登記中", "已完成")) -> 未開始
A35: P5A | B35: 11 | C35: =COUNTIFS('📱 各班抽查登記表'!$B$8:$B$227, "P5A", '📱 各班抽查登記表'!$F$8:$F$227, ">0") -> 0 | D35: =COUNTIFS('📱 各班抽查登記表'!$B$8:$B$227, "P5A", '📱 各班抽查登記表'!$H$8:$H$227, "達標") -> 0 | E35: =COUNTIFS('📱 各班抽查登記表'!$B$8:$B$227, "P5A", '📱 各班抽查登記表'!$H$8:$H$227, "超重") -> 0 | F35: =IF(C35=0, "", D35/C35) | G35: =IF(C35=0, "", E35/C35) | H35: =IF(C35=0, "未開始", IF(C35<11, "登記中", "已完成")) -> 未開始
A36: P5B | B36: 11 | C36: =COUNTIFS('📱 各班抽查登記表'!$B$8:$B$227, "P5B", '📱 各班抽查登記表'!$F$8:$F$227, ">0") -> 0 | D36: =COUNTIFS('📱 各班抽查登記表'!$B$8:$B$227, "P5B", '📱 各班抽查登記表'!$H$8:$H$227, "達標") -> 0 | E36: =COUNTIFS('📱 各班抽查登記表'!$B$8:$B$227, "P5B", '📱 各班抽查登記表'!$H$8:$H$227, "超重") -> 0 | F36: =IF(C36=0, "", D36/C36) | G36: =IF(C36=0, "", E36/C36) | H36: =IF(C36=0, "未開始", IF(C36<11, "登記中", "已完成")) -> 未開始
A37: P5C | B37: 11 | C37: =COUNTIFS('📱 各班抽查登記表'!$B$8:$B$227, "P5C", '📱 各班抽查登記表'!$F$8:$F$227, ">0") -> 0 | D37: =COUNTIFS('📱 各班抽查登記表'!$B$8:$B$227, "P5C", '📱 各班抽查登記表'!$H$8:$H$227, "達標") -> 0 | E37: =COUNTIFS('📱 各班抽查登記表'!$B$8:$B$227, "P5C", '📱 各班抽查登記表'!$H$8:$H$227, "超重") -> 0 | F37: =IF(C37=0, "", D37/C37) | G37: =IF(C37=0, "", E37/C37) | H37: =IF(C37=0, "未開始", IF(C37<11, "登記中", "已完成")) -> 未開始
A38: P6A | B38: 11 | C38: =COUNTIFS('📱 各班抽查登記表'!$B$8:$B$227, "P6A", '📱 各班抽查登記表'!$F$8:$F$227, ">0") -> 0 | D38: =COUNTIFS('📱 各班抽查登記表'!$B$8:$B$227, "P6A", '📱 各班抽查登記表'!$H$8:$H$227, "達標") -> 0 | E38: =COUNTIFS('📱 各班抽查登記表'!$B$8:$B$227, "P6A", '📱 各班抽查登記表'!$H$8:$H$227, "超重") -> 0 | F38: =IF(C38=0, "", D38/C38) | G38: =IF(C38=0, "", E38/C38) | H38: =IF(C38=0, "未開始", IF(C38<11, "登記中", "已完成")) -> 未開始
A39: P6B | B39: 11 | C39: =COUNTIFS('📱 各班抽查登記表'!$B$8:$B$227, "P6B", '📱 各班抽查登記表'!$F$8:$F$227, ">0") -> 0 | D39: =COUNTIFS('📱 各班抽查登記表'!$B$8:$B$227, "P6B", '📱 各班抽查登記表'!$H$8:$H$227, "達標") -> 0 | E39: =COUNTIFS('📱 各班抽查登記表'!$B$8:$B$227, "P6B", '📱 各班抽查登記表'!$H$8:$H$227, "超重") -> 0 | F39: =IF(C39=0, "", D39/C39) | G39: =IF(C39=0, "", E39/C39) | H39: =IF(C39=0, "未開始", IF(C39<11, "登記中", "已完成")) -> 未開始
A40: P6C | B40: 11 | C40: =COUNTIFS('📱 各班抽查登記表'!$B$8:$B$227, "P6C", '📱 各班抽查登記表'!$F$8:$F$227, ">0") -> 0 | D40: =COUNTIFS('📱 各班抽查登記表'!$B$8:$B$227, "P6C", '📱 各班抽查登記表'!$H$8:$H$227, "達標") -> 0 | E40: =COUNTIFS('📱 各班抽查登記表'!$B$8:$B$227, "P6C", '📱 各班抽查登記表'!$H$8:$H$227, "超重") -> 0 | F40: =IF(C40=0, "", D40/C40) | G40: =IF(C40=0, "", E40/C40) | H40: =IF(C40=0, "未開始", IF(C40<11, "登記中", "已完成")) -> 未開始
A41: P6D | B41: 11 | C41: =COUNTIFS('📱 各班抽查登記表'!$B$8:$B$227, "P6D", '📱 各班抽查登記表'!$F$8:$F$227, ">0") -> 0 | D41: =COUNTIFS('📱 各班抽查登記表'!$B$8:$B$227, "P6D", '📱 各班抽查登記表'!$H$8:$H$227, "達標") -> 0 | E41: =COUNTIFS('📱 各班抽查登記表'!$B$8:$B$227, "P6D", '📱 各班抽查登記表'!$H$8:$H$227, "超重") -> 0 | F41: =IF(C41=0, "", D41/C41) | G41: =IF(C41=0, "", E41/C41) | H41: =IF(C41=0, "未開始", IF(C41<11, "登記中", "已完成")) -> 未開始
A43: 四、 全校抽查學生即時明細總表 (對應『📱 各班抽查登記表』1:1 即時連動)
A45: 序號 | B45: 班別 | C45: 座號 | D45: 學生姓名 | E45: 體重 (kg) | F45: 書包重 (kg) | G45: 佔體重% | H45: 評定結果 | I45: 超重原因代號 | J45: 備註
A46: ='📱 各班抽查登記表'!A8 -> 1 | B46: ='📱 各班抽查登記表'!B8 -> P1A | C46: ='📱 各班抽查登記表'!C8 -> 0 | D46: ='📱 各班抽查登記表'!D8 | E46: ='📱 各班抽查登記表'!E8 | F46: ='📱 各班抽查登記表'!F8 -> 0 | G46: ='📱 各班抽查登記表'!G8 | H46: ='📱 各班抽查登記表'!H8 | ... J46: ='📱 各班抽查登記表'!J8 -> 0
A47: ='📱 各班抽查登記表'!A9 -> 2 | B47: ='📱 各班抽查登記表'!B9 -> P1A | C47: ='📱 各班抽查登記表'!C9 -> 0 | D47: ='📱 各班抽查登記表'!D9 | E47: ='📱 各班抽查登記表'!E9 | F47: ='📱 各班抽查登記表'!F9 -> 0 | G47: ='📱 各班抽查登記表'!G9 | H47: ='📱 各班抽查登記表'!H9 | ... J47: ='📱 各班抽查登記表'!J9 -> 0
A48: ='📱 各班抽查登記表'!A10 -> 3 | B48: ='📱 各班抽查登記表'!B10 -> P1A | C48: ='📱 各班抽查登記表'!C10 -> 0 | D48: ='📱 各班抽查登記表'!D10 | E48: ='📱 各班抽查登記表'!E10 | F48: ='📱 各班抽查登記表'!F10 -> 0 | G48: ='📱 各班抽查登記表'!G10 | H48: ='📱 各班抽查登記表'!H10 | ... J48: ='📱 各班抽查登記表'!J10 -> 0
...

Sheet 💾 學生體重資料庫
A1: 💾 26-27 學年 小學部學生體重與健康數據資料庫 (633 位學生)
A3: 檢索鍵 (班別-座號) | B3: 班別 | C3: 座號 | D3: 學生姓名 | E3: 性別 | F3: 年齡 | G3: 身高 (cm) | H3: 體重 (kg) | I3: BMI 指標
A4: P1A-1 | B4: P1A | C4: 1 | D4: 陳芊妤 | E4: F | F4: 6 | G4: 116.5 | H4: 18.5 | I4: 13.6
A5: P1A-2 | B5: P1A | C5: 2 | D5: 陳浩宇 | E5: M | F5: 6 | G5: 115 | H5: 19.1 | I5: 14.4
A6: P1A-3 | B6: P1A | C6: 3 | D6: 謝洛晴 | E6: F | F6: 6 | G6: 115.5 | H6: 16.2 | I6: 12.1
A7: P1A-4 | B7: P1A | C7: 4 | D7: 鄭煒霖 | E7: M | F7: 6 | G7: 123.5 | H7: 26.4 | I7: 17.3
A8: P1A-5 | B8: P1A | C8: 5 | D8: 張祖琛 | E8: M | F8: 6 | G8: 111 | H8: 15.4 | I8: 12.5
A9: P1A-6 | B9: P1A | C9: 6 | D9: 張珈嘉 | E9: F | F9: 6 | G9: 114.5 | H9: 17.3 | I9: 13.2
A10: P1A-7 | B10: P1A | C10: 7 | D10: 左卓熹 | E10: M | F10: 6 | G10: 114 | H10: 19.7 | I10: 15.2
A11: P1A-8 | B11: P1A | C11: 8 | D11: 鄧璟熙 | E11: M | F11: 6 | G11: 125.5 | H11: 21.9 | I11: 13.9
A12: P1A-9 | B12: P1A | C12: 9 | D12: 韓沁言 | E12: F | F12: 6 | G12: 120 | H12: 24.5 | I12: 17
A13: P1A-10 | B13: P1A | C13: 10 | D13: 楊承佳 | E13: M | F13: 6 | G13: 112.5 | H13: 16.7 | I13: 13.2
A14: P1A-11 | B14: P1A | C14: 11 | D14: 葉雨葵 | E14: F | F14: 6 | G14: 116 | H14: 21.5 | I14: 16
A15: P1A-12 | B15: P1A | C15: 12 | D15: 郭芊妤 | E15: F | F15: 6 | G15: 120 | H15: 18.8 | I15: 13.1
... A1013: ESP6B-32 | B1013: ESP6B | C1013: 32 | D1013: 嚴日禧 | E1013: M | F1013: 11 | G1013: 138.5 | H1013: 31 | I1013: 16.160774

Sheet 學生書包重量抽查結果紀錄表
A1: 學生書包重量抽查結果紀錄表 （2022/2023學年起適用）
A2: 學校名稱： | B2: 聖若瑟教區中學第五校(小學中文部) | D2: 校部編號： | E2: 051 | F2: 本學年抽查次數：
A3: 抽查教育階段： | B3: 小學教育 | D3: 抽查期間： | E3: 45922 | F3: 至 | G3: 45930
A4: 抽查教育階段總人數： | C4: 718 | D4: 抽查學生人數： | E4: 242 | F4: 抽查比率： | G4: =IFERROR(ROUND(E4/C4*100,2)," ") & "%" -> 33.7% | I4: 超重原因代號（以目測或觸感判斷來描述） ：
A5: 總計 | B5: =IFERROR("書包重量達標的學生共 "& COUNTIFS(E7:E495,">0",E7:E495,"<=0.15" ) &" 人，佔抽查學生人數百分比 "& ROUND(COUNTIFS(E7:E495,">0",E7:E495,"<=0.15" ) /E4*100,2) & " %","請輸入書包抽查重量數據") -> 書包重量達標的學生共 0 人，佔抽查學生人數百分比 0 % | I5: 1. 書包材質偏重（非拖拉式書包） 2. 水樽/壺內盛水很重 3. 書本數量多
A6: 序號 | B6: 年級 | C6: 學生體重 （ kg） | D6: 書包重量 （ kg） | E6: 書包佔體重的 百分比（%） | F6: 是否達標 （ /） | G6: 引致書包超重的原因 （ 填代號註， 可多選） | I6: 4. 作業本數量多 5. 文具及其他物品的數量多 6. 其他，須註明
A7: 1 | B7: 小一 | C7: ='📱 各班抽查登記表'!E8 | D7: ='📱 各班抽查登記表'!F8 -> 0 | E7: =IFERROR(D7/C7,0) -> 0 | F7: =IF(E7<=0.15,"","") ->  | G7: ='📱 各班抽查登記表'!I8&'📱 各班抽查登記表'!J8
A8: 2 | B8: 小一 | C8: ='📱 各班抽查登記表'!E9 | D8: ='📱 各班抽查登記表'!F9 -> 0 | E8: =IFERROR(D8/C8,0) -> 0 | F8: =IF(E8<=0.15,"","") -> 
A9: 3 | B9: 小一 | C9: ='📱 各班抽查登記表'!E10 | D9: ='📱 各班抽查登記表'!F10 -> 0 | E9: =IFERROR(D9/C9,0) -> 0 | F9: =IF(E9<=0.15,"","") -> 
A10: 4 | B10: 小一 | C10: ='📱 各班抽查登記表'!E11 | D10: ='📱 各班抽查登記表'!F11 -> 0 | E10: =IFERROR(D10/C10,0) -> 0 | F10: =IF(E10<=0.15,"","") -> 
A11: 5 | B11: 小一 | C11: ='📱 各班抽查登記表'!E12 | D11: ='📱 各班抽查登記表'!F12 -> 0 | E11: =IFERROR(D11/C11,0) -> 0 | F11: =IF(E11<=0.15,"","") -> 
A12: 6 | B12: 小一 | C12: ='📱 各班抽查登記表'!E13 | D12: ='📱 各班抽查登記表'!F13 -> 0 | E12: =IFERROR(D12/C12,0) -> 0 | F12: =IF(E12<=0.15,"","") -> 
A13: 7 | B13: 小一 | C13: ='📱 各班抽查登記表'!E14 | D13: ='📱 各班抽查登記表'!F14 -> 0 | E13: =IFERROR(D13/C13,0) -> 0 | F13: =IF(E13<=0.15,"","") -> 
A14: 8 | B14: 小一 | C14: ='📱 各班抽查登記表'!E15 | D14: ='📱 各班抽查登記表'!F15 -> 0 | E14: =IFERROR(D14/C14,0) -> 0 | F14: =IF(E14<=0.15,"","") -> 
A15: 9 | B15: 小一 | C15: ='📱 各班抽查登記表'!E16 | D15: ='📱 各班抽查登記表'!F16 -> 0 | E15: =IFERROR(D15/C15,0) -> 0 | F15: =IF(E15<=0.15,"","") -> 
A16: 10 | B16: 小一 | C16: ='📱 各班抽查登記表'!E17 | D16: ='📱 各班抽查登記表'!F17 -> 0 | E16: =IFERROR(D16/C16,0) -> 0 | F16: =IF(E16<=0.15,"","") -> 
A17: 11 | B17: 小一 | C17: ='📱 各班抽查登記表'!E18 | D17: ='📱 各班抽查登記表'!F18 -> 0 | E17: =IFERROR(D17/C17,0) -> 0 | F17: =IF(E17<=0.15,"","") -> 
A18: 12 | B18: 小一 | C18: ='📱 各班抽查登記表'!E19 | D18: ='📱 各班抽查登記表'!F19 -> 0 | E18: =IFERROR(D18/C18,0) -> 0 | F18: =IF(E18<=0.15,"","") -> 
A19: 13 | B19: 小一 | C19: ='📱 各班抽查登記表'!E20 | D19: ='📱 各班抽查登記表'!F20 -> 0 | E19: =IFERROR(D19/C19,0) -> 0 | F19: =IF(E19<=0.15,"","") -> 
... A226: 220 | B226: 小六 | C226: ='📱 各班抽查登記表'!E227 | D226: ='📱 各班抽查登記表'!F227 -> 0 | E226: =IFERROR(D226/C226,0) -> 0 | F226: =IF(E226<=0.15,"","") -> 
A227: 221 | E227: =IFERROR(D227/C227,0) -> 0 | F227: =IF(E227<=0.15,"","") -> 
A228: 222 | E228: =IFERROR(D228/C228,0) -> 0 | F228: =IF(E228<=0.15,"","") -> 
A229: 223 | E229: =IFERROR(D229/C229,0) -> 0 | F229: =IF(E229<=0.15,"","") -> 
A230: 224 | E230: =IFERROR(D230/C230,0) -> 0 | F230: =IF(E230<=0.15,"","") -> 
A231: 225 | E231: =IFERROR(D231/C231,0) -> 0 | F231: =IF(E231<=0.15,"","") -> 
A232: 226 | E232: =IFERROR(D232/C232,0) -> 0 | F232: =IF(E232<=0.15,"","") -> 
A233: 227 | E233: =IFERROR(D233/C233,0) -> 0 | F233: =IF(E233<=0.15,"","") -> 
A234: 228 | E234: =IFERROR(D234/C234,0) -> 0 | F234: =IF(E234<=0.15,"","") -> 
A235: 229 | E235: =IFERROR(D235/C235,0) -> 0 | F235: =IF(E235<=0.15,"","") -> 
A236: 230 | E236: =IFERROR(D236/C236,0) -> 0 | F236: =IF(E236<=0.15,"","") -> 
A237: 231 | E237: =IFERROR(D237/C237,0) -> 0 | F237: =IF(E237<=0.15,"","") -> 
A238: 232 | E238: =IFERROR(D238/C238,0) -> 0 | F238: =IF(E238<=0.15,"","") -> 
... A495: 489 | E495: =IFERROR(D495/C495,0) -> 0 | F495: =IF(E495<=0.15,"","") -> 
A496: 490
A497: 491
A498: 492
A499: 493
A500: 494
A501: 495
A502: 496

Sheet 學生書包重量抽查結果分析表
A1: 學生書包重量抽查結果分析表 （2022/2023學年起適用）
A2: 學校名稱： | C2: =學生書包重量抽查結果紀錄表!B2 -> 聖若瑟教區中學第五校(小學中文部) | D2: 校部編號： | E2: =學生書包重量抽查結果紀錄表!E2 -> 051
A3: 抽查期間： | C3: =TEXT(學生書包重量抽查結果紀錄表!E3,"yyyy年m月d日") & " 至 " & TEXT(學生書包重量抽查結果紀錄表!G3,"yyyy年m月d日") -> 2025年9月22日 至 2025年9月30日 | D3: 主要抽查人員： | E3: 體育/行政/培育老師
A4: 抽查教育階段： | C4: =學生書包重量抽查結果紀錄表!B3 -> 小學教育 | D4: 抽查教育階段總人數： | E4: =學生書包重量抽查結果紀錄表!C4 -> 718
A5: 抽查學生人數： | C5: =學生書包重量抽查結果紀錄表!E4 -> 242 | D5: 抽查比率： | E5: =IFERROR(ROUND(C5/E4*100,2)," ") & "%" -> 33.7%
A6: 書包超重人數： | C6: =COUNTIF(學生書包重量抽查結果紀錄表!E7:E495,">0.15") -> 0 | D6: 抽查超重比例： | E6: =IFERROR(ROUND(C6/C5*100,2)," ") & "%" -> 0%
A7: 書包達標人數： | C7: =COUNTIFS(學生書包重量抽查結果紀錄表!E7:E495,">0",學生書包重量抽查結果紀錄表!E7:E495,"<=0.15") -> 0 | D7: 抽查達標比例： | E7: =IFERROR(ROUND(C7/C5*100,2)," ") & "%" -> 0%
C8: 較前一次抽查達標改善的百分比： %（每學年第一次抽查免填） 計算方法：本次抽查達標比例 - 上次抽查達標比例
A9: 根據《學校運作指南》第三章第八節六“減輕學生書包重量”的建議，訂定完善的書包減重實施計劃： | E9: 是
A10: 學校有提供儲物空間或設備，讓學生擺放物品： | E10: 是
A11: 學生飲水機水質合符衛生標準 (最近檢查日期： 2025.08.27 ) | E11: 是
A12: 分析引致學生書包超重的主要原因：
A13: 1. | B13: 學生體重較輕
A14: 2. | B14: 書包內較多非必要學習用品
A15: 3. | B15: 書包質材較重
A16: 4. | B16: 水樽從家中盛滿水回校
A17: 5. | B17: (其他原因，請填寫)
A18: 修訂書包減重措施或策略：
A19: 1. | B19: 教導及提醒同學如何收拾書包，特別是不要帶補習社的工作紙
A20: 2. | B20: 在課室書櫃內設置空間，供學生放置不需要每天温習的書本或用品
A21: 3. | B21: 學校已添置水機，同學可帶空水樽回校盛水
A22: 4. | B22: 建議如再購買書包時，應選擇質料較輕的物料
A23: 5. | B23: 對因沒有收拾書包導致超重的同學進行複檢，並提醒家長在家檢查
A24: 註：建議因應學校情況，考慮班級規模、學生人數，以廣泛覆蓋、均衡分佈為原則進行抽查（例如各年級抽查學生人數的百分比宜相若）。

Sheet ℹ️ 使用指南與標準說明
A1: ℹ️ 26-27 學年 學生書包秤重登記系統 使用說明與即時同步機制
A3: 一、 手機快速登記與篩選步驟
A4: 1. 打開『📱 各班抽查登記表』工作頁。
A5: 2. 點擊頂部『班別』欄位的篩選圖示，選取貴班（例如 P1A）即可快速聚焦貴班欄位。
A6: 3. 隨機抽取 11 位學生，在藍色『座號』欄確認座號，並在藍色『書包重量』欄輸入秤重結果 (kg)。
A7: → 系統會自動對照體重、計算百分比，並即時判定顯示綠底【達標】或紅底【超重】。
A9: 二、 即時同步更新機制 (Real-Time Synchronous Update)
A10: • 本表格採用全動態 Excel 公式架構 (COUNTIF / COUNTIFS / 儲存格鏡像連動)。
A11: • 任何老師在『📱 各班抽查登記表』新增、修改或更新書包重量/超重原因時：
A12: 1) 登記表頂部數據卡片即時重算。
A13: 2) 『📊 全校各班抽查總表』的全校整體指標、20 班即時統計一覽表及全校明細會【100% 即時自動同步更新】！
A14: • 無需手動按下重新整理或執行巨集，修改瞬間即可在總表呈現最新結果。
... A27: 6) 其他(須註明)：其他非上述原因，請於『備註』欄位中詳細說明。
